Workbook
Name Afinador_Alumne: #N/A
Name Afinador_Comentari: #N/A
Name Afinador_Empresa: #N/A
Name Afinador_Ok: #N/A
Name Afinador_Tipus: #N/A

Sheet Alumnes
A1: # | B1: CV | C1: Cognoms | D1: Nom | E1: Nom sencer | F1: Env | G1: Reb/NT | H1: Lliure | I1: Ok | J1: Obs | K1: DNI/NIE/Passaport | L1: Data Naixement | M1: Edat | N1: Telèfon #1 | O1: Telèfon #2 | P1: TS | Q1: SS | R1: Correu electrònic | S1: Adreça | T1: Població | U1: CP | V1: Idiomes | W1: Tipus | X1: Estat | Y1: Empresa | Z1: Nom Tutor | AA1: Tel. Tutor | AB1: Correu Tutor | AC1: DNI Tutor | AD1: Inici | AE1: Fi | AF1: Hores | AG1: Observacions | AH1: Nota Empresa
A2: 1 | B2: =HYPERLINK(_xlfn.CONCAT("D:\La meva unitat\FCT\Promoció 2025-27\Alumnes\",Taula_Alumnes[[#This Row],[Nom sencer]],"\CV_",Taula_Alumnes[[#This Row],[Nom sencer]],".pdf"),"CV") -> CV | C2: Aguayo Barrientos | D2: Jose Wigberto | E2: =_xlfn.CONCAT(TRIM(Taula_Alumnes[[#This Row],[Cognoms]]), ", ", TRIM(Taula_Alumnes[[#This Row],[Nom]])) -> Aguayo Barrientos, Jose Wigberto | F2: =COUNTIF(Seguiment!F:F,Taula_Alumnes[[#This Row],[Nom sencer]]) -> 0 | G2: =COUNTIF(Seguiment!G:G,Taula_Alumnes[[#This Row],[Nom sencer]])++COUNTIF(Seguiment!H:H,Taula_Alumnes[[#This Row],[Nom sencer]]) -> 0 | H2: =IF(Taula_Alumnes[[#This Row],[Env]]=Taula_Alumnes[[#This Row],[Reb/NT]],IF(Taula_Alumnes[[#This Row],[Ok]]="Pendent","Sí","No"),"No") -> Sí | I2: =IF(Taula_Alumnes[[#This Row],[Tipus]]=Taula_Alumnes[[#This Row],[Estat]],"Assignat",IF(Taula_Alumnes[[#This Row],[Estat]]="Pràctiques finalitzades","Finalitzades","Pendent")) -> Pendent | K2: Z3653609H | L2: 39307 | M2: =_xlfn.CONCAT(TEXT(_xlfn.DAYS(TODAY(),Taula_Alumnes[[#This Row],[Data Naixement]])/365,"##")," anys") -> 19 anys | N2: 642186131 | O2: 631765167 | P2: =IFERROR(VLOOKUP(Taula_Alumnes[[#This Row],[DNI/NIE/Passaport]],Questionari!D:O,11,FALSE),"") -> AGBA 0 070813 00 9 | Q2: =IFERROR(VLOOKUP(Taula_Alumnes[[#This Row],[DNI/NIE/Passaport]],Questionari!D:O,12,FALSE),"-") -> - | R2: jw.aguayo.25@sarria.salesians.cat | S2: =IFERROR(VLOOKUP(Taula_Alumnes[[#This Row],[DNI/NIE/Passaport]],Questionari!D:O,5,FALSE),"") -> BV-2041 KM 3.5 GAVA | T2: =IFERROR(VLOOKUP(Taula_Alumnes[[#This Row],[DNI/NIE/Passaport]],Questionari!D:O,6,FALSE),"") -> GAVA | U2: =IFERROR(VLOOKUP(Taula_Alumnes[[#This Row],[DNI/NIE/Passaport]],Questionari!D:O,7,FALSE),"") -> 8850 | W2: Dual gen. | X2: Pendent | Y2: Sense empresa
A3: 2 | B3: =HYPERLINK(_xlfn.CONCAT("D:\La meva unitat\FCT\Promoció 2025-27\Alumnes\",Taula_Alumnes[[#This Row],[Nom sencer]],"\CV_",Taula_Alumnes[[#This Row],[Nom sencer]],".pdf"),"CV") -> CV | C3: Almendros García | D3: Javier | E3: =_xlfn.CONCAT(TRIM(Taula_Alumnes[[#This Row],[Cognoms]]), ", ", TRIM(Taula_Alumnes[[#This Row],[Nom]])) -> Almendros García, Javier | F3: =COUNTIF(Seguiment!F:F,Taula_Alumnes[[#This Row],[Nom sencer]]) -> 1 | G3: =COUNTIF(Seguiment!G:G,Taula_Alumnes[[#This Row],[Nom sencer]])++COUNTIF(Seguiment!H:H,Taula_Alumnes[[#This Row],[Nom sencer]]) -> 0 | H3: =IF(Taula_Alumnes[[#This Row],[Env]]=Taula_Alumnes[[#This Row],[Reb/NT]],IF(Taula_Alumnes[[#This Row],[Ok]]="Pendent","Sí","No"),"No") -> No | I3: =IF(Taula_Alumnes[[#This Row],[Tipus]]=Taula_Alumnes[[#This Row],[Estat]],"Assignat",IF(Taula_Alumnes[[#This Row],[Estat]]="Pràctiques finalitzades","Finalitzades","Pendent")) -> Assignat | K3: 47593525Q | L3: 39167 | M3: =_xlfn.CONCAT(TEXT(_xlfn.DAYS(TODAY(),Taula_Alumnes[[#This Row],[Data Naixement]])/365,"##")," anys") -> 19 anys | N3: 689066146 | O3: 636873498 | P3: =IFERROR(VLOOKUP(Taula_Alumnes[[#This Row],[DNI/NIE/Passaport]],Questionari!D:O,11,FALSE),"") -> ALGA 0 070320 00 2 | Q3: =IFERROR(VLOOKUP(Taula_Alumnes[[#This Row],[DNI/NIE/Passaport]],Questionari!D:O,12,FALSE),"-") -> 81272358665 | R3: javier.almendros@sarria.salesians.cat | S3: =IFERROR(VLOOKUP(Taula_Alumnes[[#This Row],[DNI/NIE/Passaport]],Questionari!D:O,5,FALSE),"") -> carretera reial 79 | T3: =IFERROR(VLOOKUP(Taula_Alumnes[[#This Row],[DNI/NIE/Passaport]],Questionari!D:O,6,FALSE),"") -> Sant Just Desvern | U3: =IFERROR(VLOOKUP(Taula_Alumnes[[#This Row],[DNI/NIE/Passaport]],Questionari!D:O,7,FALSE),"") -> 8960 | W3: Dual int. | X3: Dual int. | Y3: DST - Deisoltec | Z3: ALBERTO VALLE BOSACOMA | AA3: 930096914 | AB3: av@dst.es | AC3: 46743326N | AD3: 46113 | AE3: 46507 | AF3: 1000
A4: 3 | B4: =HYPERLINK(_xlfn.CONCAT("D:\La meva unitat\FCT\Promoció 2025-27\Alumnes\",Taula_Alumnes[[#This Row],[Nom sencer]],"\CV_",Taula_Alumnes[[#This Row],[Nom sencer]],".pdf"),"CV") -> CV | C4: Barrios López | D4: Iván | E4: =_xlfn.CONCAT(TRIM(Taula_Alumnes[[#This Row],[Cognoms]]), ", ", TRIM(Taula_Alumnes[[#This Row],[Nom]])) -> Barrios López, Iván | F4: =COUNTIF(Seguiment!F:F,Taula_Alumnes[[#This Row],[Nom sencer]]) -> 0 | G4: =COUNTIF(Seguiment!G:G,Taula_Alumnes[[#This Row],[Nom sencer]])++COUNTIF(Seguiment!H:H,Taula_Alumnes[[#This Row],[Nom sencer]]) -> 0 | H4: =IF(Taula_Alumnes[[#This Row],[Env]]=Taula_Alumnes[[#This Row],[Reb/NT]],IF(Taula_Alumnes[[#This Row],[Ok]]="Pendent","Sí","No"),"No") -> Sí | I4: =IF(Taula_Alumnes[[#This Row],[Tipus]]=Taula_Alumnes[[#This Row],[Estat]],"Assignat",IF(Taula_Alumnes[[#This Row],[Estat]]="Pràctiques finalitzades","Finalitzades","Pendent")) -> Pendent | J4: Ell proposa empresa | K4: 48143710H | L4: 39154 | M4: =_xlfn.CONCAT(TEXT(_xlfn.DAYS(TODAY(),Taula_Alumnes[[#This Row],[Data Naixement]])/365,"##")," anys") -> 19 anys | N4: 622851303 | O4: 936562572 | P4: =IFERROR(VLOOKUP(Taula_Alumnes[[#This Row],[DNI/NIE/Passaport]],Questionari!D:O,11,FALSE),"") -> BALO 0 070313 00 9 | Q4: =IFERROR(VLOOKUP(Taula_Alumnes[[#This Row],[DNI/NIE/Passaport]],Questionari!D:O,12,FALSE),"-") -> 81472398735 | R4: ivan.barrios@sarria.salesians.cat | S4: =IFERROR(VLOOKUP(Taula_Alumnes[[#This Row],[DNI/NIE/Passaport]],Questionari!D:O,5,FALSE),"") -> C/Salvador Allende, 7-11 | T4: =IFERROR(VLOOKUP(Taula_Alumnes[[#This Row],[DNI/NIE/Passaport]],Questionari!D:O,6,FALSE),"") -> Sant Vicenç desl Horts | U4: =IFERROR(VLOOKUP(Taula_Alumnes[[#This Row],[DNI/NIE/Passaport]],Questionari!D:O,7,FALSE),"") -> 8620 | W4: Dual int. | X4: Pendent | Y4: Sense empresa
A5: 4 | B5: =HYPERLINK(_xlfn.CONCAT("D:\La meva unitat\FCT\Promoció 2025-27\Alumnes\",Taula_Alumnes[[#This Row],[Nom sencer]],"\CV_",Taula_Alumnes[[#This Row],[Nom sencer]],".pdf"),"CV") -> CV | C5: Benítes Zambrano | D5: David | E5: =_xlfn.CONCAT(TRIM(Taula_Alumnes[[#This Row],[Cognoms]]), ", ", TRIM(Taula_Alumnes[[#This Row],[Nom]])) -> Benítes Zambrano, David | F5: =COUNTIF(Seguiment!F:F,Taula_Alumnes[[#This Row],[Nom sencer]]) -> 4 | G5: =COUNTIF(Seguiment!G:G,Taula_Alumnes[[#This Row],[Nom sencer]])++COUNTIF(Seguiment!H:H,Taula_Alumnes[[#This Row],[Nom sencer]]) -> 4 | H5: =IF(Taula_Alumnes[[#This Row],[Env]]=Taula_Alumnes[[#This Row],[Reb/NT]],IF(Taula_Alumnes[[#This Row],[Ok]]="Pendent","Sí","No"),"No") -> Sí | I5: =IF(Taula_Alumnes[[#This Row],[Tipus]]=Taula_Alumnes[[#This Row],[Estat]],"Assignat",IF(Taula_Alumnes[[#This Row],[Estat]]="Pràctiques finalitzades","Finalitzades","Pendent")) -> Pendent | K5: 48096252D | L5: 38693 | M5: =_xlfn.CONCAT(TEXT(_xlfn.DAYS(TODAY(),Taula_Alumnes[[#This Row],[Data Naixement]])/365,"##")," anys") -> 20 anys | N5: 617342497 | O5: 617342497 | P5: =IFERROR(VLOOKUP(Taula_Alumnes[[#This Row],[DNI/NIE/Passaport]],Questionari!D:O,11,FALSE),"") -> BEZA 0 051207 00 7 | Q5: =IFERROR(VLOOKUP(Taula_Alumnes[[#This Row],[DNI/NIE/Passaport]],Questionari!D:O,12,FALSE),"-") -> 81473104108 | R5: david.benites@sarria.salesians.cat | S5: =IFERROR(VLOOKUP(Taula_Alumnes[[#This Row],[DNI/NIE/Passaport]],Questionari!D:O,5,FALSE),"") -> Rambla de Mercedes, 14 | T5: =IFERROR(VLOOKUP(Taula_Alumnes[[#This Row],[DNI/NIE/Passaport]],Questionari!D:O,6,FALSE),"") -> Barcelona | U5: =IFERROR(VLOOKUP(Taula_Alumnes[[#This Row],[DNI/NIE/Passaport]],Questionari!D:O,7,FALSE),"") -> 8024 | W5: Dual int. | X5: Pendent | Y5: Sense empresa
A6: 5 | B6: =HYPERLINK(_xlfn.CONCAT("D:\La meva unitat\FCT\Promoció 2025-27\Alumnes\",Taula_Alumnes[[#This Row],[Nom sencer]],"\CV_",Taula_Alumnes[[#This Row],[Nom sencer]],".pdf"),"CV") -> CV | C6: Bonfil Valldeperas | D6: Arnau | E6: =_xlfn.CONCAT(TRIM(Taula_Alumnes[[#This Row],[Cognoms]]), ", ", TRIM(Taula_Alumnes[[#This Row],[Nom]])) -> Bonfil Valldeperas, Arnau | F6: =COUNTIF(Seguiment!F:F,Taula_Alumnes[[#This Row],[Nom sencer]]) -> 1 | G6: =COUNTIF(Seguiment!G:G,Taula_Alumnes[[#This Row],[Nom sencer]])++COUNTIF(Seguiment!H:H,Taula_Alumnes[[#This Row],[Nom sencer]]) -> 0 | H6: =IF(Taula_Alumnes[[#This Row],[Env]]=Taula_Alumnes[[#This Row],[Reb/NT]],IF(Taula_Alumnes[[#This Row],[Ok]]="Pendent","Sí","No"),"No") -> No | I6: =IF(Taula_Alumnes[[#This Row],[Tipus]]=Taula_Alumnes[[#This Row],[Estat]],"Assignat",IF(Taula_Alumnes[[#This Row],[Estat]]="Pràctiques finalitzades","Finalitzades","Pendent")) -> Pendent | J6: A partir de Juny | K6: 23867160Z | L6: 39342 | M6: =_xlfn.CONCAT(TEXT(_xlfn.DAYS(TODAY(),Taula_Alumnes[[#This Row],[Data Naixement]])/365,"##")," anys") -> 19 anys | N6: 638383900 | O6: 937772211 | P6: =IFERROR(VLOOKUP(Taula_Alumnes[[#This Row],[DNI/NIE/Passaport]],Questionari!D:O,11,FALSE),"") -> BOVA 0 070917 00 3 | Q6: =IFERROR(VLOOKUP(Taula_Alumnes[[#This Row],[DNI/NIE/Passaport]],Questionari!D:O,12,FALSE),"-") -> 81472197459 | R6: arnau.bonfil@sarria.salesians.cat | S6: =IFERROR(VLOOKUP(Taula_Alumnes[[#This Row],[DNI/NIE/Passaport]],Questionari!D:O,5,FALSE),"") -> Carrer d'Amadeu Vives 15 1r 3ra | T6: =IFERROR(VLOOKUP(Taula_Alumnes[[#This Row],[DNI/NIE/Passaport]],Questionari!D:O,6,FALSE),"") -> Esparreguera | U6: =IFERROR(VLOOKUP(Taula_Alumnes[[#This Row],[DNI/NIE/Passaport]],Questionari!D:O,7,FALSE),"") -> 8292 | W6: Dual int. | X6: Pendent Conveni | Y6: Servei Meteorologic
A7: 6 | B7: =HYPERLINK(_xlfn.CONCAT("D:\La meva unitat\FCT\Promoció 2025-27\Alumnes\",Taula_Alumnes[[#This Row],[Nom sencer]],"\CV_",Taula_Alumnes[[#This Row],[Nom sencer]],".pdf"),"CV") -> CV | C7: Camps Atmetller | D7: Jan | E7: =_xlfn.CONCAT(TRIM(Taula_Alumnes[[#This Row],[Cognoms]]), ", ", TRIM(Taula_Alumnes[[#This Row],[Nom]])) -> Camps Atmetller, Jan | F7: =COUNTIF(Seguiment!F:F,Taula_Alumnes[[#This Row],[Nom sencer]]) -> 0 | G7: =COUNTIF(Seguiment!G:G,Taula_Alumnes[[#This Row],[Nom sencer]])++COUNTIF(Seguiment!H:H,Taula_Alumnes[[#This Row],[Nom sencer]]) -> 0 | H7: =IF(Taula_Alumnes[[#This Row],[Env]]=Taula_Alumnes[[#This Row],[Reb/NT]],IF(Taula_Alumnes[[#This Row],[Ok]]="Pendent","Sí","No"),"No") -> Sí | I7: =IF(Taula_Alumnes[[#This Row],[Tipus]]=Taula_Alumnes[[#This Row],[Estat]],"Assignat",IF(Taula_Alumnes[[#This Row],[Estat]]="Pràctiques finalitzades","Finalitzades","Pendent")) -> Pendent | J7: Convalidarà | K7: 48214499J | L7: 39239 | M7: =_xlfn.CONCAT(TEXT(_xlfn.DAYS(TODAY(),Taula_Alumnes[[#This Row],[Data Naixement]])/365,"##")," anys") -> 19 anys | N7: 722586444 | O7: 936974496 | P7: =IFERROR(VLOOKUP(Taula_Alumnes[[#This Row],[DNI/NIE/Passaport]],Questionari!D:O,11,FALSE),"") -> CAAT 0 070606 01 5 | Q7: =IFERROR(VLOOKUP(Taula_Alumnes[[#This Row],[DNI/NIE/Passaport]],Questionari!D:O,12,FALSE),"-") -> 281595167663 | R7: jan.camps@sarria.salesians.cat | S7: =IFERROR(VLOOKUP(Taula_Alumnes[[#This Row],[DNI/NIE/Passaport]],Questionari!D:O,5,FALSE),"") -> Carrer Sant Jaume nº 31 | T7: =IFERROR(VLOOKUP(Taula_Alumnes[[#This Row],[DNI/NIE/Passaport]],Questionari!D:O,6,FALSE),"") -> Rubí | U7: =IFERROR(VLOOKUP(Taula_Alumnes[[#This Row],[DNI/NIE/Passaport]],Questionari!D:O,7,FALSE),"") -> 8191 | W7: Convalidació | X7: Pendent | Y7: Sense empresa
A8: 7 | B8: =HYPERLINK(_xlfn.CONCAT("D:\La meva unitat\FCT\Promoció 2025-27\Alumnes\",Taula_Alumnes[[#This Row],[Nom sencer]],"\CV_",Taula_Alumnes[[#This Row],[Nom sencer]],".pdf"),"CV") -> CV | C8: Cebrián Piñeiro | D8: Rocco | E8: =_xlfn.CONCAT(TRIM(Taula_Alumnes[[#This Row],[Cognoms]]), ", ", TRIM(Taula_Alumnes[[#This Row],[Nom]])) -> Cebrián Piñeiro, Rocco | F8: =COUNTIF(Seguiment!F:F,Taula_Alumnes[[#This Row],[Nom sencer]]) -> 0 | G8: =COUNTIF(Seguiment!G:G,Taula_Alumnes[[#This Row],[Nom sencer]])++COUNTIF(Seguiment!H:H,Taula_Alumnes[[#This Row],[Nom sencer]]) -> 0 | H8: =IF(Taula_Alumnes[[#This Row],[Env]]=Taula_Alumnes[[#This Row],[Reb/NT]],IF(Taula_Alumnes[[#This Row],[Ok]]="Pendent","Sí","No"),"No") -> Sí | I8: =IF(Taula_Alumnes[[#This Row],[Tipus]]=Taula_Alumnes[[#This Row],[Estat]],"Assignat",IF(Taula_Alumnes[[#This Row],[Estat]]="Pràctiques finalitzades","Finalitzades","Pendent")) -> Pendent | K8: 49820745P | L8: 39378 | M8: =_xlfn.CONCAT(TEXT(_xlfn.DAYS(TODAY(),Taula_Alumnes[[#This Row],[Data Naixement]])/365,"##")," anys") -> 19 anys | N8: 676023741 | O8: 656321228 | P8: =IFERROR(VLOOKUP(Taula_Alumnes[[#This Row],[DNI/NIE/Passaport]],Questionari!D:O,11,FALSE),"") -> CEPI 0 071023 00 5 | Q8: =IFERROR(VLOOKUP(Taula_Alumnes[[#This Row],[DNI/NIE/Passaport]],Questionari!D:O,12,FALSE),"-") -> 81379105448 | R8: rocco.cebrian@sarria.salesians.cat | S8: =IFERROR(VLOOKUP(Taula_Alumnes[[#This Row],[DNI/NIE/Passaport]],Questionari!D:O,5,FALSE),"") -> Carolina catasus i bosch | T8: =IFERROR(VLOOKUP(Taula_Alumnes[[#This Row],[DNI/NIE/Passaport]],Questionari!D:O,6,FALSE),"") -> Sant Feliu de Llobregat | U8: =IFERROR(VLOOKUP(Taula_Alumnes[[#This Row],[DNI/NIE/Passaport]],Questionari!D:O,7,FALSE),"") -> 8980 | W8: Dual gen. | X8: Pendent | Y8: Sense empresa
A9: 8 | B9: =HYPERLINK(_xlfn.CONCAT("D:\La meva unitat\FCT\Promoció 2025-27\Alumnes\",Taula_Alumnes[[#This Row],[Nom sencer]],"\CV_",Taula_Alumnes[[#This Row],[Nom sencer]],".pdf"),"CV") -> CV | C9: Chavero Grande | D9: Pau | E9: =_xlfn.CONCAT(TRIM(Taula_Alumnes[[#This Row],[Cognoms]]), ", ", TRIM(Taula_Alumnes[[#This Row],[Nom]])) -> Chavero Grande, Pau | F9: =COUNTIF(Seguiment!F:F,Taula_Alumnes[[#This Row],[Nom sencer]]) -> 1 | G9: =COUNTIF(Seguiment!G:G,Taula_Alumnes[[#This Row],[Nom sencer]])++COUNTIF(Seguiment!H:H,Taula_Alumnes[[#This Row],[Nom sencer]]) -> 1 | H9: =IF(Taula_Alumnes[[#This Row],[Env]]=Taula_Alumnes[[#This Row],[Reb/NT]],IF(Taula_Alumnes[[#This Row],[Ok]]="Pendent","Sí","No"),"No") -> Sí | I9: =IF(Taula_Alumnes[[#This Row],[Tipus]]=Taula_Alumnes[[#This Row],[Estat]],"Assignat",IF(Taula_Alumnes[[#This Row],[Estat]]="Pràctiques finalitzades","Finalitzades","Pendent")) -> Pendent | K9: 39479024F | L9: 39078 | M9: =_xlfn.CONCAT(TEXT(_xlfn.DAYS(TODAY(),Taula_Alumnes[[#This Row],[Data Naixement]])/365,"##")," anys") -> 19 anys | N9: 691095180 | O9: 933501731 | P9: =IFERROR(VLOOKUP(Taula_Alumnes[[#This Row],[DNI/NIE/Passaport]],Questionari!D:O,11,FALSE),"") -> CHGR 0 061227 00 5 | Q9: =IFERROR(VLOOKUP(Taula_Alumnes[[#This Row],[DNI/NIE/Passaport]],Questionari!D:O,12,FALSE),"-") -> 81472172096 | R9: pau.chavero@sarria.salesians.cat | S9: =IFERROR(VLOOKUP(Taula_Alumnes[[#This Row],[DNI/NIE/Passaport]],Questionari!D:O,5,FALSE),"") -> Carrer del japò 29 2-2 | T9: =IFERROR(VLOOKUP(Taula_Alumnes[[#This Row],[DNI/NIE/Passaport]],Questionari!D:O,6,FALSE),"") -> Barcelona | U9: =IFERROR(VLOOKUP(Taula_Alumnes[[#This Row],[DNI/NIE/Passaport]],Questionari!D:O,7,FALSE),"") -> 8016 | W9: Dual int. | X9: Pendent | Y9: Sense empresa
A10: 10 | B10: =HYPERLINK(_xlfn.CONCAT("D:\La meva unitat\FCT\Promoció 2025-27\Alumnes\",Taula_Alumnes[[#This Row],[Nom sencer]],"\CV_",Taula_Alumnes[[#This Row],[Nom sencer]],".pdf"),"CV") -> CV | C10: Corbelle Padin | D10: Iago | E10: =_xlfn.CONCAT(TRIM(Taula_Alumnes[[#This Row],[Cognoms]]), ", ", TRIM(Taula_Alumnes[[#This Row],[Nom]])) -> Corbelle Padin, Iago | F10: =COUNTIF(Seguiment!F:F,Taula_Alumnes[[#This Row],[Nom sencer]]) -> 1 | G10: =COUNTIF(Seguiment!G:G,Taula_Alumnes[[#This Row],[Nom sencer]])++COUNTIF(Seguiment!H:H,Taula_Alumnes[[#This Row],[Nom sencer]]) -> 0 | H10: =IF(Taula_Alumnes[[#This Row],[Env]]=Taula_Alumnes[[#This Row],[Reb/NT]],IF(Taula_Alumnes[[#This Row],[Ok]]="Pendent","Sí","No"),"No") -> No | I10: =IF(Taula_Alumnes[[#This Row],[Tipus]]=Taula_Alumnes[[#This Row],[Estat]],"Assignat",IF(Taula_Alumnes[[#This Row],[Estat]]="Pràctiques finalitzades","Finalitzades","Pendent")) -> Pendent | J10: Ell proposa empresa | K10: 45182681D | L10: 39291 | M10: =_xlfn.CONCAT(TEXT(_xlfn.DAYS(TODAY(),Taula_Alumnes[[#This Row],[Data Naixement]])/365,"##")," anys") -> 19 anys | N10: 648635894 | O10: 936651676 | P10: =IFERROR(VLOOKUP(Taula_Alumnes[[#This Row],[DNI/NIE/Passaport]],Questionari!D:O,11,FALSE),"") -> COPA 0 070728 00 9 | Q10: =IFERROR(VLOOKUP(Taula_Alumnes[[#This Row],[DNI/NIE/Passaport]],Questionari!D:O,12,FALSE),"-") -> 81472194126 | R10: iago.corbelle@sarria.salesians.cat | S10: =IFERROR(VLOOKUP(Taula_Alumnes[[#This Row],[DNI/NIE/Passaport]],Questionari!D:O,5,FALSE),"") -> Av 300 n83 | T10: =IFERROR(VLOOKUP(Taula_Alumnes[[#This Row],[DNI/NIE/Passaport]],Questionari!D:O,6,FALSE),"") -> Castelldefels | U10: =IFERROR(VLOOKUP(Taula_Alumnes[[#This Row],[DNI/NIE/Passaport]],Questionari!D:O,7,FALSE),"") -> 8860 | W10: Dual gen. | X10: Pendent | Y10: Sense empresa
A11: 11 | B11: =HYPERLINK(_xlfn.CONCAT("D:\La meva unitat\FCT\Promoció 2025-27\Alumnes\",Taula_Alumnes[[#This Row],[Nom sencer]],"\CV_",Taula_Alumnes[[#This Row],[Nom sencer]],".pdf"),"CV") -> CV | C11: Dublanche | D11: Alexis Stéphane Fran | E11: =_xlfn.CONCAT(TRIM(Taula_Alumnes[[#This Row],[Cognoms]]), ", ", TRIM(Taula_Alumnes[[#This Row],[Nom]])) -> Dublanche, Alexis Stéphane Fran | F11: =COUNTIF(Seguiment!F:F,Taula_Alumnes[[#This Row],[Nom sencer]]) -> 1 | G11: =COUNTIF(Seguiment!G:G,Taula_Alumnes[[#This Row],[Nom sencer]])++COUNTIF(Seguiment!H:H,Taula_Alumnes[[#This Row],[Nom sencer]]) -> 1 | H11: =IF(Taula_Alumnes[[#This Row],[Env]]=Taula_Alumnes[[#This Row],[Reb/NT]],IF(Taula_Alumnes[[#This Row],[Ok]]="Pendent","Sí","No"),"No") -> Sí | I11: =IF(Taula_Alumnes[[#This Row],[Tipus]]=Taula_Alumnes[[#This Row],[Estat]],"Assignat",IF(Taula_Alumnes[[#This Row],[Estat]]="Pràctiques finalitzades","Finalitzades","Pendent")) -> Pendent | K11: Y4571921H | L11: 39014 | M11: =_xlfn.CONCAT(TEXT(_xlfn.DAYS(TODAY(),Taula_Alumnes[[#This Row],[Data Naixement]])/365,"##")," anys") -> 20 anys | N11: 663082944 | O11: 695456973 | P11: =IFERROR(VLOOKUP(Taula_Alumnes[[#This Row],[DNI/NIE/Passaport]],Questionari!D:O,11,FALSE),"") -> DUBL 0 061024 00 9 | Q11: =IFERROR(VLOOKUP(Taula_Alumnes[[#This Row],[DNI/NIE/Passaport]],Questionari!D:O,12,FALSE),"-") -> 81513502685 | R11: asf.dublanche@sarria.salesians.cat | S11: =IFERROR(VLOOKUP(Taula_Alumnes[[#This Row],[DNI/NIE/Passaport]],Questionari!D:O,5,FALSE),"") -> Carrer del Dipòsit, 6 | T11: =IFERROR(VLOOKUP(Taula_Alumnes[[#This Row],[DNI/NIE/Passaport]],Questionari!D:O,6,FALSE),"") -> Sant Cugat del Vallès | U11: =IFERROR(VLOOKUP(Taula_Alumnes[[#This Row],[DNI/NIE/Passaport]],Questionari!D:O,7,FALSE),"") -> 8198 | W11: Dual int. | X11: Pendent | Y11: Sense empresa
A12: 13 | B12: =HYPERLINK(_xlfn.CONCAT("D:\La meva unitat\FCT\Promoció 2025-27\Alumnes\",Taula_Alumnes[[#This Row],[Nom sencer]],"\CV_",Taula_Alumnes[[#This Row],[Nom sencer]],".pdf"),"CV") -> CV | C12: Espejo Martínez | D12: Ivan | E12: =_xlfn.CONCAT(TRIM(Taula_Alumnes[[#This Row],[Cognoms]]), ", ", TRIM(Taula_Alumnes[[#This Row],[Nom]])) -> Espejo Martínez, Ivan | F12: =COUNTIF(Seguiment!F:F,Taula_Alumnes[[#This Row],[Nom sencer]]) -> 1 | G12: =COUNTIF(Seguiment!G:G,Taula_Alumnes[[#This Row],[Nom sencer]])++COUNTIF(Seguiment!H:H,Taula_Alumnes[[#This Row],[Nom sencer]]) -> 0 | H12: =IF(Taula_Alumnes[[#This Row],[Env]]=Taula_Alumnes[[#This Row],[Reb/NT]],IF(Taula_Alumnes[[#This Row],[Ok]]="Pendent","Sí","No"),"No") -> No | I12: =IF(Taula_Alumnes[[#This Row],[Tipus]]=Taula_Alumnes[[#This Row],[Estat]],"Assignat",IF(Taula_Alumnes[[#This Row],[Estat]]="Pràctiques finalitzades","Finalitzades","Pendent")) -> Assignat | K12: 47264213H | L12: 38734 | M12: =_xlfn.CONCAT(TEXT(_xlfn.DAYS(TODAY(),Taula_Alumnes[[#This Row],[Data Naixement]])/365,"##")," anys") -> 20 anys | N12: 679330382 | O12: 933360808 | P12: =IFERROR(VLOOKUP(Taula_Alumnes[[#This Row],[DNI/NIE/Passaport]],Questionari!D:O,11,FALSE),"") -> ESMA 0 060117 00 9 | Q12: =IFERROR(VLOOKUP(Taula_Alumnes[[#This Row],[DNI/NIE/Passaport]],Questionari!D:O,12,FALSE),"-") -> 81472210391 | R12: ivan.espejo@sarria.salesians.cat | S12: =IFERROR(VLOOKUP(Taula_Alumnes[[#This Row],[DNI/NIE/Passaport]],Questionari!D:O,5,FALSE),"") -> Carrer Igualtat 51-53 1rA Esc.Izq | T12: =IFERROR(VLOOKUP(Taula_Alumnes[[#This Row],[DNI/NIE/Passaport]],Questionari!D:O,6,FALSE),"") -> L'Hospitalet de Llobregat | U12: =IFERROR(VLOOKUP(Taula_Alumnes[[#This Row],[DNI/NIE/Passaport]],Questionari!D:O,7,FALSE),"") -> 8902 | W12: Dual int. | X12: Dual int. | Y12: TOBEIT SL | Z12: Daniel Roldan Buades | AA12: 637205861 | AB12: d.roldan@tobeit.es | AC12: 48575707Y | AD12: 46119 | AE12: 46437 | AF12: 1014
A13: 14 | B13: =HYPERLINK(_xlfn.CONCAT("D:\La meva unitat\FCT\Promoció 2025-27\Alumnes\",Taula_Alumnes[[#This Row],[Nom sencer]],"\CV_",Taula_Alumnes[[#This Row],[Nom sencer]],".pdf"),"CV") -> CV | C13: Farré Marín | D13: Joan | E13: =_xlfn.CONCAT(TRIM(Taula_Alumnes[[#This Row],[Cognoms]]), ", ", TRIM(Taula_Alumnes[[#This Row],[Nom]])) -> Farré Marín, Joan | F13: =COUNTIF(Seguiment!F:F,Taula_Alumnes[[#This Row],[Nom sencer]]) -> 0 | G13: =COUNTIF(Seguiment!G:G,Taula_Alumnes[[#This Row],[Nom sencer]])++COUNTIF(Seguiment!H:H,Taula_Alumnes[[#This Row],[Nom sencer]]) -> 0 | H13: =IF(Taula_Alumnes[[#This Row],[Env]]=Taula_Alumnes[[#This Row],[Reb/NT]],IF(Taula_Alumnes[[#This Row],[Ok]]="Pendent","Sí","No"),"No") -> Sí | I13: =IF(Taula_Alumnes[[#This Row],[Tipus]]=Taula_Alumnes[[#This Row],[Estat]],"Assignat",IF(Taula_Alumnes[[#This Row],[Estat]]="Pràctiques finalitzades","Finalitzades","Pendent")) -> Pendent | K13: 48073477G | L13: 38782 | M13: =_xlfn.CONCAT(TEXT(_xlfn.DAYS(TODAY(),Taula_Alumnes[[#This Row],[Data Naixement]])/365,"##")," anys") -> 20 anys | N13: 673319530 | P13: =IFERROR(VLOOKUP(Taula_Alumnes[[#This Row],[DNI/NIE/Passaport]],Questionari!D:O,11,FALSE),"") -> FAMA 0 060306 00 2 | Q13: =IFERROR(VLOOKUP(Taula_Alumnes[[#This Row],[DNI/NIE/Passaport]],Questionari!D:O,12,FALSE),"-") -> 81499953910 | R13: joan.farre.25@sarria.salesians.cat | S13: =IFERROR(VLOOKUP(Taula_Alumnes[[#This Row],[DNI/NIE/Passaport]],Questionari!D:O,5,FALSE),"") -> C: Ma Aurelia Capmany 18, 1-1 | T13: =IFERROR(VLOOKUP(Taula_Alumnes[[#This Row],[DNI/NIE/Passaport]],Questionari!D:O,6,FALSE),"") -> Cornella De Llobregat | U13: =IFERROR(VLOOKUP(Taula_Alumnes[[#This Row],[DNI/NIE/Passaport]],Questionari!D:O,7,FALSE),"") -> 8940 | W13: Dual int. | X13: Pendent | Y13: Sense empresa
A14: 15 | B14: =HYPERLINK(_xlfn.CONCAT("D:\La meva unitat\FCT\Promoció 2025-27\Alumnes\",Taula_Alumnes[[#This Row],[Nom sencer]],"\CV_",Taula_Alumnes[[#This Row],[Nom sencer]],".pdf"),"CV") -> CV | C14: Fernandes Teixeira | D14: Sebastian Samuel | E14: =_xlfn.CONCAT(TRIM(Taula_Alumnes[[#This Row],[Cognoms]]), ", ", TRIM(Taula_Alumnes[[#This Row],[Nom]])) -> Fernandes Teixeira, Sebastian Samuel | F14: =COUNTIF(Seguiment!F:F,Taula_Alumnes[[#This Row],[Nom sencer]]) -> 3 | G14: =COUNTIF(Seguiment!G:G,Taula_Alumnes[[#This Row],[Nom sencer]])++COUNTIF(Seguiment!H:H,Taula_Alumnes[[#This Row],[Nom sencer]]) -> 2 | H14: =IF(Taula_Alumnes[[#This Row],[Env]]=Taula_Alumnes[[#This Row],[Reb/NT]],IF(Taula_Alumnes[[#This Row],[Ok]]="Pendent","Sí","No"),"No") -> No | I14: =IF(Taula_Alumnes[[#This Row],[Tipus]]=Taula_Alumnes[[#This Row],[Estat]],"Assignat",IF(Taula_Alumnes[[#This Row],[Estat]]="Pràctiques finalitzades","Finalitzades","Pendent")) -> Assignat | K14: Y5172222L | L14: 38468 | M14: =_xlfn.CONCAT(TEXT(_xlfn.DAYS(TODAY(),Taula_Alumnes[[#This Row],[Data Naixement]])/365,"##")," anys") -> 21 anys | N14: 662933188 | O14: 698309619 | P14: =IFERROR(VLOOKUP(Taula_Alumnes[[#This Row],[DNI/NIE/Passaport]],Questionari!D:O,11,FALSE),"") -> FETE 0 050426 00 4 | Q14: =IFERROR(VLOOKUP(Taula_Alumnes[[#This Row],[DNI/NIE/Passaport]],Questionari!D:O,12,FALSE),"-") -> 81357068563 | R14: ss.fernandes@sarria.salesians.cat | S14: =IFERROR(VLOOKUP(Taula_Alumnes[[#This Row],[DNI/NIE/Passaport]],Questionari!D:O,5,FALSE),"") -> Avinguda del Puig de Rimila 10 | T14: =IFERROR(VLOOKUP(Taula_Alumnes[[#This Row],[DNI/NIE/Passaport]],Questionari!D:O,6,FALSE),"") -> Sant Cugat del Vallès | U14: =IFERROR(VLOOKUP(Taula_Alumnes[[#This Row],[DNI/NIE/Passaport]],Questionari!D:O,7,FALSE),"") -> 8173 | W14: Dual int. | X14: Dual int. | Y14: Ingens-Networks | Z14: José Pintado | AA14: 934226655 | AB14: jose.pintado@ingens-networks.com | AC14: 43447542J | AD14: 46147 | AE14: 46535 | AF14: 980
A15: 16 | B15: =HYPERLINK(_xlfn.CONCAT("D:\La meva unitat\FCT\Promoció 2025-27\Alumnes\",Taula_Alumnes[[#This Row],[Nom sencer]],"\CV_",Taula_Alumnes[[#This Row],[Nom sencer]],".pdf"),"CV") -> CV | C15: Gallego Pérez | D15: Dídac | E15: =_xlfn.CONCAT(TRIM(Taula_Alumnes[[#This Row],[Cognoms]]), ", ", TRIM(Taula_Alumnes[[#This Row],[Nom]])) -> Gallego Pérez, Dídac | F15: =COUNTIF(Seguiment!F:F,Taula_Alumnes[[#This Row],[Nom sencer]]) -> 0 | G15: =COUNTIF(Seguiment!G:G,Taula_Alumnes[[#This Row],[Nom sencer]])++COUNTIF(Seguiment!H:H,Taula_Alumnes[[#This Row],[Nom sencer]]) -> 0 | H15: =IF(Taula_Alumnes[[#This Row],[Env]]=Taula_Alumnes[[#This Row],[Reb/NT]],IF(Taula_Alumnes[[#This Row],[Ok]]="Pendent","Sí","No"),"No") -> Sí | I15: =IF(Taula_Alumnes[[#This Row],[Tipus]]=Taula_Alumnes[[#This Row],[Estat]],"Assignat",IF(Taula_Alumnes[[#This Row],[Estat]]="Pràctiques finalitzades","Finalitzades","Pendent")) -> Pendent | J15: A partir de Setembre, està cobrant l'atur | K15: 49931779K | L15: 38840 | M15: =_xlfn.CONCAT(TEXT(_xlfn.DAYS(TODAY(),Taula_Alumnes[[#This Row],[Data Naixement]])/365,"##")," anys") -> 20 anys | N15: 651854058 | O15: 622543517 | P15: =IFERROR(VLOOKUP(Taula_Alumnes[[#This Row],[DNI/NIE/Passaport]],Questionari!D:O,11,FALSE),"") | Q15: =IFERROR(VLOOKUP(Taula_Alumnes[[#This Row],[DNI/NIE/Passaport]],Questionari!D:O,12,FALSE),"-") -> - | R15: didac.gallego@sarria.salesians.cat | S15: =IFERROR(VLOOKUP(Taula_Alumnes[[#This Row],[DNI/NIE/Passaport]],Questionari!D:O,5,FALSE),"") | T15: =IFERROR(VLOOKUP(Taula_Alumnes[[#This Row],[DNI/NIE/Passaport]],Questionari!D:O,6,FALSE),"") | U15: =IFERROR(VLOOKUP(Taula_Alumnes[[#This Row],[DNI/NIE/Passaport]],Questionari!D:O,7,FALSE),"") | W15: Dual int. | X15: Pendent | Y15: Sense empresa
A16: 17 | B16: =HYPERLINK(_xlfn.CONCAT("D:\La meva unitat\FCT\Promoció 2025-27\Alumnes\",Taula_Alumnes[[#This Row],[Nom sencer]],"\CV_",Taula_Alumnes[[#This Row],[Nom sencer]],".pdf"),"CV") -> CV | C16: Guerra Alberti | D16: Edgar | E16: =_xlfn.CONCAT(TRIM(Taula_Alumnes[[#This Row],[Cognoms]]), ", ", TRIM(Taula_Alumnes[[#This Row],[Nom]])) -> Guerra Alberti, Edgar | F16: =COUNTIF(Seguiment!F:F,Taula_Alumnes[[#This Row],[Nom sencer]]) -> 0 | G16: =COUNTIF(Seguiment!G:G,Taula_Alumnes[[#This Row],[Nom sencer]])++COUNTIF(Seguiment!H:H,Taula_Alumnes[[#This Row],[Nom sencer]]) -> 0 | H16: =IF(Taula_Alumnes[[#This Row],[Env]]=Taula_Alumnes[[#This Row],[Reb/NT]],IF(Taula_Alumnes[[#This Row],[Ok]]="Pendent","Sí","No"),"No") -> Sí | I16: =IF(Taula_Alumnes[[#This Row],[Tipus]]=Taula_Alumnes[[#This Row],[Estat]],"Assignat",IF(Taula_Alumnes[[#This Row],[Estat]]="Pràctiques finalitzades","Finalitzades","Pendent")) -> Pendent | J16: Ell proposa empresa | K16: 39403670R | L16: 34367 | M16: =_xlfn.CONCAT(TEXT(_xlfn.DAYS(TODAY(),Taula_Alumnes[[#This Row],[Data Naixement]])/365,"##")," anys") -> 32 anys | N16: 691138993 | P16: =IFERROR(VLOOKUP(Taula_Alumnes[[#This Row],[DNI/NIE/Passaport]],Questionari!D:O,11,FALSE),"") -> GUAL 0 940202 00 2 | Q16: =IFERROR(VLOOKUP(Taula_Alumnes[[#This Row],[DNI/NIE/Passaport]],Questionari!D:O,12,FALSE),"-") -> 81217190826 | R16: edgar.guerra.25@sarria.salesians.cat | S16: =IFERROR(VLOOKUP(Taula_Alumnes[[#This Row],[DNI/NIE/Passaport]],Questionari!D:O,5,FALSE),"") -> Rambla Badal 36, 5-2, Escalera B | T16: =IFERROR(VLOOKUP(Taula_Alumnes[[#This Row],[DNI/NIE/Passaport]],Questionari!D:O,6,FALSE),"") -> Barcelona | U16: =IFERROR(VLOOKUP(Taula_Alumnes[[#This Row],[DNI/NIE/Passaport]],Questionari!D:O,7,FALSE),"") -> 8014 | W16: Dual int. | X16: Pendent | Y16: Sense empresa
A17: 18 | B17: =HYPERLINK(_xlfn.CONCAT("D:\La meva unitat\FCT\Promoció 2025-27\Alumnes\",Taula_Alumnes[[#This Row],[Nom sencer]],"\CV_",Taula_Alumnes[[#This Row],[Nom sencer]],".pdf"),"CV") -> CV | C17: Guillamon Uzñate | D17: Arnau | E17: =_xlfn.CONCAT(TRIM(Taula_Alumnes[[#This Row],[Cognoms]]), ", ", TRIM(Taula_Alumnes[[#This Row],[Nom]])) -> Guillamon Uzñate, Arnau | F17: =COUNTIF(Seguiment!F:F,Taula_Alumnes[[#This Row],[Nom sencer]]) -> 4 | G17: =COUNTIF(Seguiment!G:G,Taula_Alumnes[[#This Row],[Nom sencer]])++COUNTIF(Seguiment!H:H,Taula_Alumnes[[#This Row],[Nom sencer]]) -> 1 | H17: =IF(Taula_Alumnes[[#This Row],[Env]]=Taula_Alumnes[[#This Row],[Reb/NT]],IF(Taula_Alumnes[[#This Row],[Ok]]="Pendent","Sí","No"),"No") -> No | I17: =IF(Taula_Alumnes[[#This Row],[Tipus]]=Taula_Alumnes[[#This Row],[Estat]],"Assignat",IF(Taula_Alumnes[[#This Row],[Estat]]="Pràctiques finalitzades","Finalitzades","Pendent")) -> Pendent | K17: 49782841P | L17: 39063 | M17: =_xlfn.CONCAT(TEXT(_xlfn.DAYS(TODAY(),Taula_Alumnes[[#This Row],[Data Naixement]])/365,"##")," anys") -> 19 anys | N17: 645922414 | O17: 934742414 | P17: =IFERROR(VLOOKUP(Taula_Alumnes[[#This Row],[DNI/NIE/Passaport]],Questionari!D:O,11,FALSE),"") -> GUUZ 0 061212 00 3 | Q17: =IFERROR(VLOOKUP(Taula_Alumnes[[#This Row],[DNI/NIE/Passaport]],Questionari!D:O,12,FALSE),"-") -> 81377464734 | R17: arnau.guillamon@sarria.salesians.cat | S17: =IFERROR(VLOOKUP(Taula_Alumnes[[#This Row],[DNI/NIE/Passaport]],Questionari!D:O,5,FALSE),"") -> Joana Raspall 11 | T17: =IFERROR(VLOOKUP(Taula_Alumnes[[#This Row],[DNI/NIE/Passaport]],Questionari!D:O,6,FALSE),"") -> Sant Feliu de Llobregat | U17: =IFERROR(VLOOKUP(Taula_Alumnes[[#This Row],[DNI/NIE/Passaport]],Questionari!D:O,7,FALSE),"") -> 8980 | W17: Dual gen. | X17: Pendent Conveni | Y17: NetLand
A18: 19 | B18: =HYPERLINK(_xlfn.CONCAT("D:\La meva unitat\FCT\Promoció 2025-27\Alumnes\",Taula_Alumnes[[#This Row],[Nom sencer]],"\CV_",Taula_Alumnes[[#This Row],[Nom sencer]],".pdf"),"CV") -> CV | C18: Jurado Borrell | D18: Hugo | E18: =_xlfn.CONCAT(TRIM(Taula_Alumnes[[#This Row],[Cognoms]]), ", ", TRIM(Taula_Alumnes[[#This Row],[Nom]])) -> Jurado Borrell, Hugo | F18: =COUNTIF(Seguiment!F:F,Taula_Alumnes[[#This Row],[Nom sencer]]) -> 2 | G18: =COUNTIF(Seguiment!G:G,Taula_Alumnes[[#This Row],[Nom sencer]])++COUNTIF(Seguiment!H:H,Taula_Alumnes[[#This Row],[Nom sencer]]) -> 2 | H18: =IF(Taula_Alumnes[[#This Row],[Env]]=Taula_Alumnes[[#This Row],[Reb/NT]],IF(Taula_Alumnes[[#This Row],[Ok]]="Pendent","Sí","No"),"No") -> Sí | I18: =IF(Taula_Alumnes[[#This Row],[Tipus]]=Taula_Alumnes[[#This Row],[Estat]],"Assignat",IF(Taula_Alumnes[[#This Row],[Estat]]="Pràctiques finalitzades","Finalitzades","Pendent")) -> Pendent | K18: 23926317S | L18: 39162 | M18: =_xlfn.CONCAT(TEXT(_xlfn.DAYS(TODAY(),Taula_Alumnes[[#This Row],[Data Naixement]])/365,"##")," anys") -> 19 anys | N18: 639339785 | O18: 639339785 | P18: =IFERROR(VLOOKUP(Taula_Alumnes[[#This Row],[DNI/NIE/Passaport]],Questionari!D:O,11,FALSE),"") -> JUBO 0 070321 00 5 | Q18: =IFERROR(VLOOKUP(Taula_Alumnes[[#This Row],[DNI/NIE/Passaport]],Questionari!D:O,12,FALSE),"-") -> 81378007227 | R18: hugo.jurado@sarria.salesians.cat | S18: =IFERROR(VLOOKUP(Taula_Alumnes[[#This Row],[DNI/NIE/Passaport]],Questionari!D:O,5,FALSE),"") -> Avinguda de Josep Ferrer i Domingo, 4 | T18: =IFERROR(VLOOKUP(Taula_Alumnes[[#This Row],[DNI/NIE/Passaport]],Questionari!D:O,6,FALSE),"") -> Rubí | U18: =IFERROR(VLOOKUP(Taula_Alumnes[[#This Row],[DNI/NIE/Passaport]],Questionari!D:O,7,FALSE),"") -> 8191 | W18: Dual int. | X18: Pendent | Y18: Sense empresa
A19: 20 | B19: =HYPERLINK(_xlfn.CONCAT("D:\La meva unitat\FCT\Promoció 2025-27\Alumnes\",Taula_Alumnes[[#This Row],[Nom sencer]],"\CV_",Taula_Alumnes[[#This Row],[Nom sencer]],".pdf"),"CV") -> CV | C19: Lucas Jerez | D19: Hector | E19: =_xlfn.CONCAT(TRIM(Taula_Alumnes[[#This Row],[Cognoms]]), ", ", TRIM(Taula_Alumnes[[#This Row],[Nom]])) -> Lucas Jerez, Hector | F19: =COUNTIF(Seguiment!F:F,Taula_Alumnes[[#This Row],[Nom sencer]]) -> 1 | G19: =COUNTIF(Seguiment!G:G,Taula_Alumnes[[#This Row],[Nom sencer]])++COUNTIF(Seguiment!H:H,Taula_Alumnes[[#This Row],[Nom sencer]]) -> 0 | H19: =IF(Taula_Alumnes[[#This Row],[Env]]=Taula_Alumnes[[#This Row],[Reb/NT]],IF(Taula_Alumnes[[#This Row],[Ok]]="Pendent","Sí","No"),"No") -> No | I19: =IF(Taula_Alumnes[[#This Row],[Tipus]]=Taula_Alumnes[[#This Row],[Estat]],"Assignat",IF(Taula_Alumnes[[#This Row],[Estat]]="Pràctiques finalitzades","Finalitzades","Pendent")) -> Assignat | K19: 49287946G | L19: 39258 | M19: =_xlfn.CONCAT(TEXT(_xlfn.DAYS(TODAY(),Taula_Alumnes[[#This Row],[Data Naixement]])/365,"##")," anys") -> 19 anys | N19: 607407685 | O19: 937759573 | P19: =IFERROR(VLOOKUP(Taula_Alumnes[[#This Row],[DNI/NIE/Passaport]],Questionari!D:O,11,FALSE),"") -> LUJE 0 070625 00 5 | Q19: =IFERROR(VLOOKUP(Taula_Alumnes[[#This Row],[DNI/NIE/Passaport]],Questionari!D:O,12,FALSE),"-") -> 81472197863 | R19: hector.lucas@sarria.salesians.cat | S19: =IFERROR(VLOOKUP(Taula_Alumnes[[#This Row],[DNI/NIE/Passaport]],Questionari!D:O,5,FALSE),"") -> Carrer Ullastrell, 38 08630 Abrera, Barcelona | T19: =IFERROR(VLOOKUP(Taula_Alumnes[[#This Row],[DNI/NIE/Passaport]],Questionari!D:O,6,FALSE),"") -> Abrera | U19: =IFERROR(VLOOKUP(Taula_Alumnes[[#This Row],[DNI/NIE/Passaport]],Questionari!D:O,7,FALSE),"") -> 8630 | W19: Dual gen. | X19: Dual gen. | Y19: DeInfo | Z19: Guillermo Puig Sans | AA19: 934176400 | AB19: gpuig@deinfo.es | AC19: 46126178T | AD19: 46119 | AE19: 46203 | AF19: 320 | AG19: Faltaran hores
A20: 22 | B20: =HYPERLINK(_xlfn.CONCAT("D:\La meva unitat\FCT\Promoció 2025-27\Alumnes\",Taula_Alumnes[[#This Row],[Nom sencer]],"\CV_",Taula_Alumnes[[#This Row],[Nom sencer]],".pdf"),"CV") -> CV | C20: Miller Villalobos | D20: Sheila | E20: =_xlfn.CONCAT(TRIM(Taula_Alumnes[[#This Row],[Cognoms]]), ", ", TRIM(Taula_Alumnes[[#This Row],[Nom]])) -> Miller Villalobos, Sheila | F20: =COUNTIF(Seguiment!F:F,Taula_Alumnes[[#This Row],[Nom sencer]]) -> 4 | G20: =COUNTIF(Seguiment!G:G,Taula_Alumnes[[#This Row],[Nom sencer]])++COUNTIF(Seguiment!H:H,Taula_Alumnes[[#This Row],[Nom sencer]]) -> 3 | H20: =IF(Taula_Alumnes[[#This Row],[Env]]=Taula_Alumnes[[#This Row],[Reb/NT]],IF(Taula_Alumnes[[#This Row],[Ok]]="Pendent","Sí","No"),"No") -> No | I20: =IF(Taula_Alumnes[[#This Row],[Tipus]]=Taula_Alumnes[[#This Row],[Estat]],"Assignat",IF(Taula_Alumnes[[#This Row],[Estat]]="Pràctiques finalitzades","Finalitzades","Pendent")) -> Assignat | K20: 49184848S | L20: 39322 | M20: =_xlfn.CONCAT(TEXT(_xlfn.DAYS(TODAY(),Taula_Alumnes[[#This Row],[Data Naixement]])/365,"##")," anys") -> 19 anys | N20: 602464071 | O20: 691041967 | P20: =IFERROR(VLOOKUP(Taula_Alumnes[[#This Row],[DNI/NIE/Passaport]],Questionari!D:O,11,FALSE),"") -> MIVI 1 070828 00 6 | Q20: =IFERROR(VLOOKUP(Taula_Alumnes[[#This Row],[DNI/NIE/Passaport]],Questionari!D:O,12,FALSE),"-") -> 81516553236 | R20: sheila.miller.25@sarria.salesians.cat | S20: =IFERROR(VLOOKUP(Taula_Alumnes[[#This Row],[DNI/NIE/Passaport]],Questionari!D:O,5,FALSE),"") -> Carrer Mineria 1, esc.A, pis 5, porta 8 | T20: =IFERROR(VLOOKUP(Taula_Alumnes[[#This Row],[DNI/NIE/Passaport]],Questionari!D:O,6,FALSE),"") -> Barcelona | U20: =IFERROR(VLOOKUP(Taula_Alumnes[[#This Row],[DNI/NIE/Passaport]],Questionari!D:O,7,FALSE),"") -> 8038 | W20: Dual gen. | X20: Dual gen. | Y20: Atrevia | Z20: MARCO ARROM ZANUTTI | AA20: 630106718 | AB20: marrom@atrevia.com | AC20: 53412413L | AD20: 46160 | AE20: 46220 | AF20: 291 | AG20: Faltaran hores
A21: 23 | B21: =HYPERLINK(_xlfn.CONCAT("D:\La meva unitat\FCT\Promoció 2025-27\Alumnes\",Taula_Alumnes[[#This Row],[Nom sencer]],"\CV_",Taula_Alumnes[[#This Row],[Nom sencer]],".pdf"),"CV") -> CV | C21: Miravete Núñez | D21: Tristan | E21: =_xlfn.CONCAT(TRIM(Taula_Alumnes[[#This Row],[Cognoms]]), ", ", TRIM(Taula_Alumnes[[#This Row],[Nom]])) -> Miravete Núñez, Tristan | F21: =COUNTIF(Seguiment!F:F,Taula_Alumnes[[#This Row],[Nom sencer]]) -> 1 | G21: =COUNTIF(Seguiment!G:G,Taula_Alumnes[[#This Row],[Nom sencer]])++COUNTIF(Seguiment!H:H,Taula_Alumnes[[#This Row],[Nom sencer]]) -> 1 | H21: =IF(Taula_Alumnes[[#This Row],[Env]]=Taula_Alumnes[[#This Row],[Reb/NT]],IF(Taula_Alumnes[[#This Row],[Ok]]="Pendent","Sí","No"),"No") -> Sí | I21: =IF(Taula_Alumnes[[#This Row],[Tipus]]=Taula_Alumnes[[#This Row],[Estat]],"Assignat",IF(Taula_Alumnes[[#This Row],[Estat]]="Pràctiques finalitzades","Finalitzades","Pendent")) -> Pendent | K21: 51289091B | L21: 38141 | M21: =_xlfn.CONCAT(TEXT(_xlfn.DAYS(TODAY(),Taula_Alumnes[[#This Row],[Data Naixement]])/365,"##")," anys") -> 22 anys | N21: 672729689 | O21: 664837283 | P21: =IFERROR(VLOOKUP(Taula_Alumnes[[#This Row],[DNI/NIE/Passaport]],Questionari!D:O,11,FALSE),"") -> MINU 0 040603 00 4 | Q21: =IFERROR(VLOOKUP(Taula_Alumnes[[#This Row],[DNI/NIE/Passaport]],Questionari!D:O,12,FALSE),"-") -> 81345281346 | R21: tristan.miravete@sarria.salesians.cat | S21: =IFERROR(VLOOKUP(Taula_Alumnes[[#This Row],[DNI/NIE/Passaport]],Questionari!D:O,5,FALSE),"") -> Carrer Calabria 33 5,2 | T21: =IFERROR(VLOOKUP(Taula_Alumnes[[#This Row],[DNI/NIE/Passaport]],Questionari!D:O,6,FALSE),"") -> Barcelona | U21: =IFERROR(VLOOKUP(Taula_Alumnes[[#This Row],[DNI/NIE/Passaport]],Questionari!D:O,7,FALSE),"") -> 8015 | W21: Dual gen. | X21: Pendent | Y21: Sense empresa
A22: 24 | B22: =HYPERLINK(_xlfn.CONCAT("D:\La meva unitat\FCT\Promoció 2025-27\Alumnes\",Taula_Alumnes[[#This Row],[Nom sencer]],"\CV_",Taula_Alumnes[[#This Row],[Nom sencer]],".pdf"),"CV") -> CV | C22: Pérez Hernando | D22: Álvaro | E22: =_xlfn.CONCAT(TRIM(Taula_Alumnes[[#This Row],[Cognoms]]), ", ", TRIM(Taula_Alumnes[[#This Row],[Nom]])) -> Pérez Hernando, Álvaro | F22: =COUNTIF(Seguiment!F:F,Taula_Alumnes[[#This Row],[Nom sencer]]) -> 0 | G22: =COUNTIF(Seguiment!G:G,Taula_Alumnes[[#This Row],[Nom sencer]])++COUNTIF(Seguiment!H:H,Taula_Alumnes[[#This Row],[Nom sencer]]) -> 0 | H22: =IF(Taula_Alumnes[[#This Row],[Env]]=Taula_Alumnes[[#This Row],[Reb/NT]],IF(Taula_Alumnes[[#This Row],[Ok]]="Pendent","Sí","No"),"No") -> Sí | I22: =IF(Taula_Alumnes[[#This Row],[Tipus]]=Taula_Alumnes[[#This Row],[Estat]],"Assignat",IF(Taula_Alumnes[[#This Row],[Estat]]="Pràctiques finalitzades","Finalitzades","Pendent")) -> Pendent | K22: 48143661S | L22: 39035 | M22: =_xlfn.CONCAT(TEXT(_xlfn.DAYS(TODAY(),Taula_Alumnes[[#This Row],[Data Naixement]])/365,"##")," anys") -> 20 anys | N22: 663910905 | O22: 678348239 | P22: =IFERROR(VLOOKUP(Taula_Alumnes[[#This Row],[DNI/NIE/Passaport]],Questionari!D:O,11,FALSE),"") -> PEHE 0 061114 00 1 | Q22: =IFERROR(VLOOKUP(Taula_Alumnes[[#This Row],[DNI/NIE/Passaport]],Questionari!D:O,12,FALSE),"-") -> 81473024686 | R22: alvaro.perez@sarria.salesians.cat | S22: =IFERROR(VLOOKUP(Taula_Alumnes[[#This Row],[DNI/NIE/Passaport]],Questionari!D:O,5,FALSE),"") -> Carrer Enric Prat de la Riba, 43 | T22: =IFERROR(VLOOKUP(Taula_Alumnes[[#This Row],[DNI/NIE/Passaport]],Questionari!D:O,6,FALSE),"") -> Gelida | U22: =IFERROR(VLOOKUP(Taula_Alumnes[[#This Row],[DNI/NIE/Passaport]],Questionari!D:O,7,FALSE),"") -> 8790 | W22: Convalidació | X22: Pendent | Y22: Sense empresa
A23: 25 | B23: =HYPERLINK(_xlfn.CONCAT("D:\La meva unitat\FCT\Promoció 2025-27\Alumnes\",Taula_Alumnes[[#This Row],[Nom sencer]],"\CV_",Taula_Alumnes[[#This Row],[Nom sencer]],".pdf"),"CV") -> CV | C23: Pesado Flores | D23: Samuel | E23: =_xlfn.CONCAT(TRIM(Taula_Alumnes[[#This Row],[Cognoms]]), ", ", TRIM(Taula_Alumnes[[#This Row],[Nom]])) -> Pesado Flores, Samuel | F23: =COUNTIF(Seguiment!F:F,Taula_Alumnes[[#This Row],[Nom sencer]]) -> 0 | G23: =COUNTIF(Seguiment!G:G,Taula_Alumnes[[#This Row],[Nom sencer]])++COUNTIF(Seguiment!H:H,Taula_Alumnes[[#This Row],[Nom sencer]]) -> 0 | H23: =IF(Taula_Alumnes[[#This Row],[Env]]=Taula_Alumnes[[#This Row],[Reb/NT]],IF(Taula_Alumnes[[#This Row],[Ok]]="Pendent","Sí","No"),"No") -> Sí | I23: =IF(Taula_Alumnes[[#This Row],[Tipus]]=Taula_Alumnes[[#This Row],[Estat]],"Assignat",IF(Taula_Alumnes[[#This Row],[Estat]]="Pràctiques finalitzades","Finalitzades","Pendent")) -> Pendent | K23: 49550677Y | L23: 39365 | M23: =_xlfn.CONCAT(TEXT(_xlfn.DAYS(TODAY(),Taula_Alumnes[[#This Row],[Data Naixement]])/365,"##")," anys") -> 19 anys | N23: 640862329 | O23: 640862329 | P23: =IFERROR(VLOOKUP(Taula_Alumnes[[#This Row],[DNI/NIE/Passaport]],Questionari!D:O,11,FALSE),"") -> PEFL 0 071010 00 3 | Q23: =IFERROR(VLOOKUP(Taula_Alumnes[[#This Row],[DNI/NIE/Passaport]],Questionari!D:O,12,FALSE),"-") -> 81472251013 | R23: samuel.pesado@sarria.salesians.cat | S23: =IFERROR(VLOOKUP(Taula_Alumnes[[#This Row],[DNI/NIE/Passaport]],Questionari!D:O,5,FALSE),"") -> cami de can oriol | T23: =IFERROR(VLOOKUP(Taula_Alumnes[[#This Row],[DNI/NIE/Passaport]],Questionari!D:O,6,FALSE),"") -> Rubí | U23: =IFERROR(VLOOKUP(Taula_Alumnes[[#This Row],[DNI/NIE/Passaport]],Questionari!D:O,7,FALSE),"") -> 8191 | W23: Dual gen. | X23: Pendent | Y23: Sense empresa
A24: 26 | B24: =HYPERLINK(_xlfn.CONCAT("D:\La meva unitat\FCT\Promoció 2025-27\Alumnes\",Taula_Alumnes[[#This Row],[Nom sencer]],"\CV_",Taula_Alumnes[[#This Row],[Nom sencer]],".pdf"),"CV") -> CV | C24: Ricote Fernández | D24: Marc | E24: =_xlfn.CONCAT(TRIM(Taula_Alumnes[[#This Row],[Cognoms]]), ", ", TRIM(Taula_Alumnes[[#This Row],[Nom]])) -> Ricote Fernández, Marc | F24: =COUNTIF(Seguiment!F:F,Taula_Alumnes[[#This Row],[Nom sencer]]) -> 0 | G24: =COUNTIF(Seguiment!G:G,Taula_Alumnes[[#This Row],[Nom sencer]])++COUNTIF(Seguiment!H:H,Taula_Alumnes[[#This Row],[Nom sencer]]) -> 0 | H24: =IF(Taula_Alumnes[[#This Row],[Env]]=Taula_Alumnes[[#This Row],[Reb/NT]],IF(Taula_Alumnes[[#This Row],[Ok]]="Pendent","Sí","No"),"No") -> No | I24: =IF(Taula_Alumnes[[#This Row],[Tipus]]=Taula_Alumnes[[#This Row],[Estat]],"Assignat",IF(Taula_Alumnes[[#This Row],[Estat]]="Pràctiques finalitzades","Finalitzades","Pendent")) -> Assignat | J24: Ja té empresa | K24: 49323013L | L24: 39282 | M24: =_xlfn.CONCAT(TEXT(_xlfn.DAYS(TODAY(),Taula_Alumnes[[#This Row],[Data Naixement]])/365,"##")," anys") -> 19 anys | N24: 688785765 | O24: 601254487 | P24: =IFERROR(VLOOKUP(Taula_Alumnes[[#This Row],[DNI/NIE/Passaport]],Questionari!D:O,11,FALSE),"") -> RIFE 0 070719 00 5 | Q24: =IFERROR(VLOOKUP(Taula_Alumnes[[#This Row],[DNI/NIE/Passaport]],Questionari!D:O,12,FALSE),"-") -> 81516648822 | R24: marc.ricote@sarria.salesians.cat | S24: =IFERROR(VLOOKUP(Taula_Alumnes[[#This Row],[DNI/NIE/Passaport]],Questionari!D:O,5,FALSE),"") -> Passeig de la zona franca 208, ESC IZQ ATCO 2 | T24: =IFERROR(VLOOKUP(Taula_Alumnes[[#This Row],[DNI/NIE/Passaport]],Questionari!D:O,6,FALSE),"") -> Barcelona | U24: =IFERROR(VLOOKUP(Taula_Alumnes[[#This Row],[DNI/NIE/Passaport]],Questionari!D:O,7,FALSE),"") -> 8038 | W24: Dual gen. | X24: Dual gen. | Y24: Frigicoll | Z24: DAVID SAEZ RODRIGUEZ | AA24: 934803322 | AB24: david.saez@frigicoll.es | AC24: 46452673X | AD24: 46119 | AE24: 46220 | AF24: 424 | AG24: Faltaran hores
A25: 27 | B25: =HYPERLINK(_xlfn.CONCAT("D:\La meva unitat\FCT\Promoció 2025-27\Alumnes\",Taula_Alumnes[[#This Row],[Nom sencer]],"\CV_",Taula_Alumnes[[#This Row],[Nom sencer]],".pdf"),"CV") -> CV | C25: Rodríguez González | D25: Mario | E25: =_xlfn.CONCAT(TRIM(Taula_Alumnes[[#This Row],[Cognoms]]), ", ", TRIM(Taula_Alumnes[[#This Row],[Nom]])) -> Rodríguez González, Mario | F25: =COUNTIF(Seguiment!F:F,Taula_Alumnes[[#This Row],[Nom sencer]]) -> 3 | G25: =COUNTIF(Seguiment!G:G,Taula_Alumnes[[#This Row],[Nom sencer]])++COUNTIF(Seguiment!H:H,Taula_Alumnes[[#This Row],[Nom sencer]]) -> 3 | H25: =IF(Taula_Alumnes[[#This Row],[Env]]=Taula_Alumnes[[#This Row],[Reb/NT]],IF(Taula_Alumnes[[#This Row],[Ok]]="Pendent","Sí","No"),"No") -> Sí | I25: =IF(Taula_Alumnes[[#This Row],[Tipus]]=Taula_Alumnes[[#This Row],[Estat]],"Assignat",IF(Taula_Alumnes[[#This Row],[Estat]]="Pràctiques finalitzades","Finalitzades","Pendent")) -> Pendent | K25: 54331383Q | L25: 38964 | M25: =_xlfn.CONCAT(TEXT(_xlfn.DAYS(TODAY(),Taula_Alumnes[[#This Row],[Data Naixement]])/365,"##")," anys") -> 20 anys | N25: 644417955 | O25: 616432401 | P25: =IFERROR(VLOOKUP(Taula_Alumnes[[#This Row],[DNI/NIE/Passaport]],Questionari!D:O,11,FALSE),"") -> ROGO 0 060904 00 3 | Q25: =IFERROR(VLOOKUP(Taula_Alumnes[[#This Row],[DNI/NIE/Passaport]],Questionari!D:O,12,FALSE),"-") -> 81376947705 | R25: mario.rodriguez@sarria.salesians.cat | S25: =IFERROR(VLOOKUP(Taula_Alumnes[[#This Row],[DNI/NIE/Passaport]],Questionari!D:O,5,FALSE),"") -> Carrer San Sebastián 110, Sant Cugat del Vallès | T25: =IFERROR(VLOOKUP(Taula_Alumnes[[#This Row],[DNI/NIE/Passaport]],Questionari!D:O,6,FALSE),"") -> Sant Cugat del Vallès | U25: =IFERROR(VLOOKUP(Taula_Alumnes[[#This Row],[DNI/NIE/Passaport]],Questionari!D:O,7,FALSE),"") -> 8195 | W25: Dual int. | X25: Pendent | Y25: Sense empresa
A26: 28 | B26: =HYPERLINK(_xlfn.CONCAT("D:\La meva unitat\FCT\Promoció 2025-27\Alumnes\",Taula_Alumnes[[#This Row],[Nom sencer]],"\CV_",Taula_Alumnes[[#This Row],[Nom sencer]],".pdf"),"CV") -> CV | C26: Sánchez Herrera | D26: Andres Mauricio | E26: =_xlfn.CONCAT(TRIM(Taula_Alumnes[[#This Row],[Cognoms]]), ", ", TRIM(Taula_Alumnes[[#This Row],[Nom]])) -> Sánchez Herrera, Andres Mauricio | F26: =COUNTIF(Seguiment!F:F,Taula_Alumnes[[#This Row],[Nom sencer]]) -> 0 | G26: =COUNTIF(Seguiment!G:G,Taula_Alumnes[[#This Row],[Nom sencer]])++COUNTIF(Seguiment!H:H,Taula_Alumnes[[#This Row],[Nom sencer]]) -> 0 | H26: =IF(Taula_Alumnes[[#This Row],[Env]]=Taula_Alumnes[[#This Row],[Reb/NT]],IF(Taula_Alumnes[[#This Row],[Ok]]="Pendent","Sí","No"),"No") -> Sí | I26: =IF(Taula_Alumnes[[#This Row],[Tipus]]=Taula_Alumnes[[#This Row],[Estat]],"Assignat",IF(Taula_Alumnes[[#This Row],[Estat]]="Pràctiques finalitzades","Finalitzades","Pendent")) -> Pendent | J26: Posposada a un 3er | K26: 55654151Q | L26: 35376 | M26: =_xlfn.CONCAT(TEXT(_xlfn.DAYS(TODAY(),Taula_Alumnes[[#This Row],[Data Naixement]])/365,"##")," anys") -> 30 anys | N26: 662535065 | P26: =IFERROR(VLOOKUP(Taula_Alumnes[[#This Row],[DNI/NIE/Passaport]],Questionari!D:O,11,FALSE),"") -> SAHE 0 961107 00 4 | Q26: =IFERROR(VLOOKUP(Taula_Alumnes[[#This Row],[DNI/NIE/Passaport]],Questionari!D:O,12,FALSE),"-") -> 81455961679 | R26: am.sanchez.25@sarria.salesians.cat | S26: =IFERROR(VLOOKUP(Taula_Alumnes[[#This Row],[DNI/NIE/Passaport]],Questionari!D:O,5,FALSE),"") -> andyvmpier@gmail.com | T26: =IFERROR(VLOOKUP(Taula_Alumnes[[#This Row],[DNI/NIE/Passaport]],Questionari!D:O,6,FALSE),"") -> L'Hospitalet de Llobregat | U26: =IFERROR(VLOOKUP(Taula_Alumnes[[#This Row],[DNI/NIE/Passaport]],Questionari!D:O,7,FALSE),"") -> 8905 | W26: Posposada | X26: Pendent | Y26: Sense empresa
A27: 29 | B27: =HYPERLINK(_xlfn.CONCAT("D:\La meva unitat\FCT\Promoció 2025-27\Alumnes\",Taula_Alumnes[[#This Row],[Nom sencer]],"\CV_",Taula_Alumnes[[#This Row],[Nom sencer]],".pdf"),"CV") -> CV | C27: Simarro González | D27: Izan | E27: =_xlfn.CONCAT(TRIM(Taula_Alumnes[[#This Row],[Cognoms]]), ", ", TRIM(Taula_Alumnes[[#This Row],[Nom]])) -> Simarro González, Izan | F27: =COUNTIF(Seguiment!F:F,Taula_Alumnes[[#This Row],[Nom sencer]]) -> 2 | G27: =COUNTIF(Seguiment!G:G,Taula_Alumnes[[#This Row],[Nom sencer]])++COUNTIF(Seguiment!H:H,Taula_Alumnes[[#This Row],[Nom sencer]]) -> 2 | H27: =IF(Taula_Alumnes[[#This Row],[Env]]=Taula_Alumnes[[#This Row],[Reb/NT]],IF(Taula_Alumnes[[#This Row],[Ok]]="Pendent","Sí","No"),"No") -> Sí | I27: =IF(Taula_Alumnes[[#This Row],[Tipus]]=Taula_Alumnes[[#This Row],[Estat]],"Assignat",IF(Taula_Alumnes[[#This Row],[Estat]]="Pràctiques finalitzades","Finalitzades","Pendent")) -> Pendent | K27: 26060226F | L27: 39111 | M27: =_xlfn.CONCAT(TEXT(_xlfn.DAYS(TODAY(),Taula_Alumnes[[#This Row],[Data Naixement]])/365,"##")," anys") -> 19 anys | N27: 620993816 | O27: 934211118 | P27: =IFERROR(VLOOKUP(Taula_Alumnes[[#This Row],[DNI/NIE/Passaport]],Questionari!D:O,11,FALSE),"") -> SIGO 0 070129 00 5 | Q27: =IFERROR(VLOOKUP(Taula_Alumnes[[#This Row],[DNI/NIE/Passaport]],Questionari!D:O,12,FALSE),"-") -> 81472138350 | R27: izan.simarro@sarria.salesians.cat | S27: =IFERROR(VLOOKUP(Taula_Alumnes[[#This Row],[DNI/NIE/Passaport]],Questionari!D:O,5,FALSE),"") -> Carrer Gernika, 1-5, 6º 4 | T27: =IFERROR(VLOOKUP(Taula_Alumnes[[#This Row],[DNI/NIE/Passaport]],Questionari!D:O,6,FALSE),"") -> Barcelona | U27: =IFERROR(VLOOKUP(Taula_Alumnes[[#This Row],[DNI/NIE/Passaport]],Questionari!D:O,7,FALSE),"") -> 8038 | W27: Dual gen. | X27: Pendent | Y27: Sense empresa
A28: 30 | B28: =HYPERLINK(_xlfn.CONCAT("D:\La meva unitat\FCT\Promoció 2025-27\Alumnes\",Taula_Alumnes[[#This Row],[Nom sencer]],"\CV_",Taula_Alumnes[[#This Row],[Nom sencer]],".pdf"),"CV") -> CV | C28: Xu | D28: Montserrat | E28: =_xlfn.CONCAT(TRIM(Taula_Alumnes[[#This Row],[Cognoms]]), ", ", TRIM(Taula_Alumnes[[#This Row],[Nom]])) -> Xu, Montserrat | F28: =COUNTIF(Seguiment!F:F,Taula_Alumnes[[#This Row],[Nom sencer]]) -> 2 | G28: =COUNTIF(Seguiment!G:G,Taula_Alumnes[[#This Row],[Nom sencer]])++COUNTIF(Seguiment!H:H,Taula_Alumnes[[#This Row],[Nom sencer]]) -> 1 | H28: =IF(Taula_Alumnes[[#This Row],[Env]]=Taula_Alumnes[[#This Row],[Reb/NT]],IF(Taula_Alumnes[[#This Row],[Ok]]="Pendent","Sí","No"),"No") -> No | I28: =IF(Taula_Alumnes[[#This Row],[Tipus]]=Taula_Alumnes[[#This Row],[Estat]],"Assignat",IF(Taula_Alumnes[[#This Row],[Estat]]="Pràctiques finalitzades","Finalitzades","Pendent")) -> Assignat | K28: X9833125G | L28: 38926 | M28: =_xlfn.CONCAT(TEXT(_xlfn.DAYS(TODAY(),Taula_Alumnes[[#This Row],[Data Naixement]])/365,"##")," anys") -> 20 anys | N28: 695210605 | O28: 695210605 | P28: =IFERROR(VLOOKUP(Taula_Alumnes[[#This Row],[DNI/NIE/Passaport]],Questionari!D:O,11,FALSE),"") -> XUXX 1 060728 00 1 | Q28: =IFERROR(VLOOKUP(Taula_Alumnes[[#This Row],[DNI/NIE/Passaport]],Questionari!D:O,12,FALSE),"-") -> 81472210694 | R28: montserrat.xu@sarria.salesians.cat | S28: =IFERROR(VLOOKUP(Taula_Alumnes[[#This Row],[DNI/NIE/Passaport]],Questionari!D:O,5,FALSE),"") -> Pl. d'Europa, 14, 15A | T28: =IFERROR(VLOOKUP(Taula_Alumnes[[#This Row],[DNI/NIE/Passaport]],Questionari!D:O,6,FALSE),"") -> L'Hospitalet de Llobregat | U28: =IFERROR(VLOOKUP(Taula_Alumnes[[#This Row],[DNI/NIE/Passaport]],Questionari!D:O,7,FALSE),"") -> 8902 | W28: Dual gen. | X28: Dual gen. | Y28: Vanture ESS | Z28: Manuel Rato De Juan | AA28: 935453880 | AB28: manuel.rato@vantureess.com | AC28: 44019171T | AD28: 46174 | AE28: 46220 | AF28: 272 | AG28: Faltaran hores
A29: 31 | B29: =HYPERLINK(_xlfn.CONCAT("D:\La meva unitat\FCT\Promoció 2025-27\Alumnes\",Taula_Alumnes[[#This Row],[Nom sencer]],"\CV_",Taula_Alumnes[[#This Row],[Nom sencer]],".pdf"),"CV") -> CV | C29: Xufré Prieto | D29: Biel | E29: =_xlfn.CONCAT(TRIM(Taula_Alumnes[[#This Row],[Cognoms]]), ", ", TRIM(Taula_Alumnes[[#This Row],[Nom]])) -> Xufré Prieto, Biel | F29: =COUNTIF(Seguiment!F:F,Taula_Alumnes[[#This Row],[Nom sencer]]) -> 0 | G29: =COUNTIF(Seguiment!G:G,Taula_Alumnes[[#This Row],[Nom sencer]])++COUNTIF(Seguiment!H:H,Taula_Alumnes[[#This Row],[Nom sencer]]) -> 0 | H29: =IF(Taula_Alumnes[[#This Row],[Env]]=Taula_Alumnes[[#This Row],[Reb/NT]],IF(Taula_Alumnes[[#This Row],[Ok]]="Pendent","Sí","No"),"No") -> Sí | I29: =IF(Taula_Alumnes[[#This Row],[Tipus]]=Taula_Alumnes[[#This Row],[Estat]],"Assignat",IF(Taula_Alumnes[[#This Row],[Estat]]="Pràctiques finalitzades","Finalitzades","Pendent")) -> Pendent | K29: 49531031W | L29: 39354 | M29: =_xlfn.CONCAT(TEXT(_xlfn.DAYS(TODAY(),Taula_Alumnes[[#This Row],[Data Naixement]])/365,"##")," anys") -> 19 anys | N29: 694489035 | O29: 652949187 | P29: =IFERROR(VLOOKUP(Taula_Alumnes[[#This Row],[DNI/NIE/Passaport]],Questionari!D:O,11,FALSE),"") -> XUPR 0 070929 00 4 | Q29: =IFERROR(VLOOKUP(Taula_Alumnes[[#This Row],[DNI/NIE/Passaport]],Questionari!D:O,12,FALSE),"-") -> 81471670124 | R29: biel.xufre.25@sarria.salesians.cat | S29: =IFERROR(VLOOKUP(Taula_Alumnes[[#This Row],[DNI/NIE/Passaport]],Questionari!D:O,5,FALSE),"") -> Carre Sant Joan 39 | T29: =IFERROR(VLOOKUP(Taula_Alumnes[[#This Row],[DNI/NIE/Passaport]],Questionari!D:O,6,FALSE),"") -> Esparreguera | U29: =IFERROR(VLOOKUP(Taula_Alumnes[[#This Row],[DNI/NIE/Passaport]],Questionari!D:O,7,FALSE),"") -> 8292 | W29: Dual gen. | X29: Pendent | Y29: Sense empresa

Sheet Empreses
A1: Sense empresa | B1: Nom contacte | C1: Correu electrònic | D1: Telèfon | E1: Adreça | F1: Nom Tutor | G1: Correu Tutor | H1: DNI Tutor | I1: Altres | J1: # Alum. | K1: # Contactes
A2: TOBEIT SL | B2: Marta García de Pruneda Pascual | C2: m.pruneda@tobeit.es | J2: =COUNTIF(Alumnes!AE:AE,Taula_Empreses[[#This Row],[Sense empresa]]) -> 0 | K2: =COUNTIF(Seguiment!C:C,Taula_Empreses[[#This Row],[Sense empresa]]) -> 4
A3: Sidogras y Flex Internacional | B3: Francisco Barrios | C3: fbarrios@sidogras.com | J3: =COUNTIF(Alumnes!AE:AE,Taula_Empreses[[#This Row],[Sense empresa]]) -> 0 | K3: =COUNTIF(Seguiment!C:C,Taula_Empreses[[#This Row],[Sense empresa]]) -> 4
A4: OUA Gestió del Territori i Urbanisme S. L. | B4: Rocio Huertas Valera | C4: r.huertas@ouagroup.com | D4: 695723022 | E4: Carrer Viladomat 317 entresol (08029 - Barcelona) | J4: =COUNTIF(Alumnes!AE:AE,Taula_Empreses[[#This Row],[Sense empresa]]) -> 0 | K4: =COUNTIF(Seguiment!C:C,Taula_Empreses[[#This Row],[Sense empresa]]) -> 6
A5: DST - Deisoltec | B5: Alberto Valle | C5: av@dst.es | F5: Alberto Valle | G5: av@dst.es | H5: 46743326N | J5: =COUNTIF(Alumnes!AE:AE,Taula_Empreses[[#This Row],[Sense empresa]]) -> 0 | K5: =COUNTIF(Seguiment!C:C,Taula_Empreses[[#This Row],[Sense empresa]]) -> 5
A6: Plural Informática | B6: Danny Toma | C6: danny@pluralinformatica.com | D6: 679 616 484 | E6: Aprestadora 12, Ent. 1ª (08902 - L’Hospitalet de Llobregat) | J6: =COUNTIF(Alumnes!AE:AE,Taula_Empreses[[#This Row],[Sense empresa]]) -> 0 | K6: =COUNTIF(Seguiment!C:C,Taula_Empreses[[#This Row],[Sense empresa]]) -> 4
A7: MK Development | B7: Elena Cócera Pérez | C7: ecocera@mkdevelopment.es | D7: 621 29 60 97 | J7: =COUNTIF(Alumnes!AE:AE,Taula_Empreses[[#This Row],[Sense empresa]]) -> 0 | K7: =COUNTIF(Seguiment!C:C,Taula_Empreses[[#This Row],[Sense empresa]]) -> 2
A8: Ingens-Networks | B8: Judith Lopez | C8: judith.lopez@ingens-networks.com | J8: =COUNTIF(Alumnes!AE:AE,Taula_Empreses[[#This Row],[Sense empresa]]) -> 0 | K8: =COUNTIF(Seguiment!C:C,Taula_Empreses[[#This Row],[Sense empresa]]) -> 6
A9: Fundació i2CAT | B9: Cristina Martín Luján | C9: cristina.martin@fundacionrandstad.es | D9: 667181688 | J9: =COUNTIF(Alumnes!AE:AE,Taula_Empreses[[#This Row],[Sense empresa]]) -> 0 | K9: =COUNTIF(Seguiment!C:C,Taula_Empreses[[#This Row],[Sense empresa]]) -> 0
A10: Larian Studios Spain SL | B10: Jorge Cabezas Garcia | C10: jorge.cabezas@larian.com | D10: 652934609 | E10: Consell de Cent 367 (08009 - Barcelona) | J10: =COUNTIF(Alumnes!AE:AE,Taula_Empreses[[#This Row],[Sense empresa]]) -> 0 | K10: =COUNTIF(Seguiment!C:C,Taula_Empreses[[#This Row],[Sense empresa]]) -> 6
A11: Fundación Randstad | B11: Cristina Martín Luján | C11: cristina.martin@fundacionrandstad.es | D11: 667181688 | E11: Barcelona | J11: =COUNTIF(Alumnes!AE:AE,Taula_Empreses[[#This Row],[Sense empresa]]) -> 0 | K11: =COUNTIF(Seguiment!C:C,Taula_Empreses[[#This Row],[Sense empresa]]) -> 4
A12: Frigicoll | B12: Sara Parada | C12: sara.parada@frigicoll.es | D12: 651027070 | I12: Segón contacte: Elena Macias (elena.macias@frigicoll.es) | J12: =COUNTIF(Alumnes!AE:AE,Taula_Empreses[[#This Row],[Sense empresa]]) -> 0 | K12: =COUNTIF(Seguiment!C:C,Taula_Empreses[[#This Row],[Sense empresa]]) -> 1
A13: Sirt | B13: Sandra Monleón | C13: smonleon@sirt.com | D13: 659 942 425 | E13: Carrer de Pere IV, 78, 8-1, Sant Martí (08005 - Barcelona) | J13: =COUNTIF(Alumnes!AE:AE,Taula_Empreses[[#This Row],[Sense empresa]]) -> 0 | K13: =COUNTIF(Seguiment!C:C,Taula_Empreses[[#This Row],[Sense empresa]]) -> 1
A14: DeInfo | B14: Guillermo | C14: gpuig@deinfo.es | D14: 934176400 | E14: Vía Augusta 261-263 Bajos B (08017 - Barcelona) | J14: =COUNTIF(Alumnes!AE:AE,Taula_Empreses[[#This Row],[Sense empresa]]) -> 0 | K14: =COUNTIF(Seguiment!C:C,Taula_Empreses[[#This Row],[Sense empresa]]) -> 5
A15: Eada | B15: Natalia Alvaro | C15: nalvaro@eada.edu | D15: 621 687546 | E15: Carrer Provença 216 (08036 - Barcelona) | J15: =COUNTIF(Alumnes!AE:AE,Taula_Empreses[[#This Row],[Sense empresa]]) -> 0 | K15: =COUNTIF(Seguiment!C:C,Taula_Empreses[[#This Row],[Sense empresa]]) -> 5
A16: NetLand | B16: Jesus Martinez | C16: jesus@netland.pro | D16: 93 228 97 09 | E16: Carrer Estelí, 33 (08980 - Sant Feliu de Llobregat) | J16: =COUNTIF(Alumnes!AE:AE,Taula_Empreses[[#This Row],[Sense empresa]]) -> 0 | K16: =COUNTIF(Seguiment!C:C,Taula_Empreses[[#This Row],[Sense empresa]]) -> 7
A17: Servei Meteorologic | B17: SARA CANALEJO CERVERA | C17: SARA.CANALEJO@GENCAT.CAT | J17: =COUNTIF(Alumnes!AE:AE,Taula_Empreses[[#This Row],[Sense empresa]]) -> 0 | K17: =COUNTIF(Seguiment!C:C,Taula_Empreses[[#This Row],[Sense empresa]]) -> 8
A18: Deutsche Telekom Global Business ( T-Systems) | B18: Josep Llena | C18: JOSE.LLENA-CRISPI@telekom.com | J18: =COUNTIF(Alumnes!AE:AE,Taula_Empreses[[#This Row],[Sense empresa]]) -> 0 | K18: =COUNTIF(Seguiment!C:C,Taula_Empreses[[#This Row],[Sense empresa]]) -> 4
A19: Atrevia | B19: Cristina Flores Frasquet | C19: cflores@atrevia.com | D19: 667 631 633 | J19: =COUNTIF(Alumnes!AE:AE,Taula_Empreses[[#This Row],[Sense empresa]]) -> 0 | K19: =COUNTIF(Seguiment!C:C,Taula_Empreses[[#This Row],[Sense empresa]]) -> 7
A20: Vanture ESS | B20: Amanda Casado | C20: Amanda.casado@vantureess.com | D20: 672 632 687 | J20: =COUNTIF(Alumnes!AE:AE,Taula_Empreses[[#This Row],[Sense empresa]]) -> 0 | K20: =COUNTIF(Seguiment!C:C,Taula_Empreses[[#This Row],[Sense empresa]]) -> 7
A21: NetLand | B21: Jesus Martinez | C21: jesus@netland.pro | J21: =COUNTIF(Alumnes!AE:AE,Taula_Empreses[[#This Row],[Sense empresa]]) -> 0 | K21: =COUNTIF(Seguiment!C:C,Taula_Empreses[[#This Row],[Sense empresa]]) -> 7
A22: Fast Byte | B22: Jordi Lanza | C22: jordi@fastbyte.es | D22: 618247848 | J22: =COUNTIF(Alumnes!AE:AE,Taula_Empreses[[#This Row],[Sense empresa]]) -> 0 | K22: =COUNTIF(Seguiment!C:C,Taula_Empreses[[#This Row],[Sense empresa]]) -> 4
A23: Solucions informàtiques Kaizen | B23: Santiago Galiano Roig | C23: santiago@sikaizen.com | D23: 931600006 | J23: =COUNTIF(Alumnes!AE:AE,Taula_Empreses[[#This Row],[Sense empresa]]) -> 0 | K23: =COUNTIF(Seguiment!C:C,Taula_Empreses[[#This Row],[Sense empresa]]) -> 2

Sheet Seguiment
A1: Data | B1: Alumne | C1: Empresa | D1: Comentari | E1: Obs | F1: CV - Enviat | G1: CV - Rebutjat | H1: CV - No l'han tractat | I1: Empresa enviada | J1: Estat | K1: Nom Empresa
A2: 46070 | B2: Espejo Martínez, Ivan | C2: TOBEIT SL | D2: CV - Enviat | F2: =IF(Taula_Seguiment[[#This Row],[Comentari]]=F$1,Taula_Seguiment[[#This Row],[Alumne]],"") -> Espejo Martínez, Ivan | G2: =IF(Taula_Seguiment[[#This Row],[Comentari]]=G$1,Taula_Seguiment[[#This Row],[Alumne]],"") | H2: =IF(Taula_Seguiment[[#This Row],[Comentari]]=H$1,Taula_Seguiment[[#This Row],[Alumne]],"") | I2: =IF(Taula_Seguiment[[#This Row],[Empresa]]="","",_xlfn.CONCAT(Taula_Seguiment[[#This Row],[Empresa]]," (",TEXT(Taula_Seguiment[[#This Row],[Data]],"dd/mm/aaaa"),")")) -> TOBEIT SL (17/02/2026) | J2: =IFERROR(VLOOKUP(Taula_Seguiment[[#This Row],[Alumne]],Alumnes!E:AE,18,FALSE),"") -> 0 | K2: =IFERROR(VLOOKUP(Taula_Seguiment[[#This Row],[Alumne]],Alumnes!E:AE,19,FALSE),"") -> Dual int.
A3: 46070 | B3: Rodríguez González, Mario | C3: TOBEIT SL | D3: CV - Enviat | F3: =IF(Taula_Seguiment[[#This Row],[Comentari]]=F$1,Taula_Seguiment[[#This Row],[Alumne]],"") -> Rodríguez González, Mario | G3: =IF(Taula_Seguiment[[#This Row],[Comentari]]=G$1,Taula_Seguiment[[#This Row],[Alumne]],"") | H3: =IF(Taula_Seguiment[[#This Row],[Comentari]]=H$1,Taula_Seguiment[[#This Row],[Alumne]],"") | I3: =IF(Taula_Seguiment[[#This Row],[Empresa]]="","",_xlfn.CONCAT(Taula_Seguiment[[#This Row],[Empresa]]," (",TEXT(Taula_Seguiment[[#This Row],[Data]],"dd/mm/aaaa"),")")) -> TOBEIT SL (17/02/2026) | J3: =IFERROR(VLOOKUP(Taula_Seguiment[[#This Row],[Alumne]],Alumnes!E:AE,18,FALSE),"") -> 0 | K3: =IFERROR(VLOOKUP(Taula_Seguiment[[#This Row],[Alumne]],Alumnes!E:AE,19,FALSE),"") -> Dual int.
